Workbook

Sheet Reporte Dirección
A1: REPORTE SEMANAL DE GASTOS DE CAMPO — TSDOCS
A2: Período 01/06 al 07/06 · Gastos NO pagados ni contabilizados en Finnegans (en plataforma TSDOCS)
A3: Importes en pesos ($). Estados: Pivot = pend. de autorizar · Gerente = asignado, pend. de autorizar · Analista = autorizado, pend. de pago · Verificado = pasado/listo para pagar
A4: TOTAL GASTOS | C4: COMPROBANTES | E4: AUTORIZADO, PEND. DE PAGO (Analista) | G4: PASADO A PAGAR (Verificado)
A5: =G27 -> 22875581 | C5: =COUNTA(I9:I26) -> 18 | E5: =SUMIF(F9:F26,"Analista",G9:G26) -> 6994373.2 | G5: =SUMIF(F9:F26,"Verificado",G9:G26) -> 15881208
A8: Autorizante | B8: Proveedor | C8: Campo | D8: Unidad / Centro de Costo | E8: Detalle del gasto | F8: Estado | G8: Importe ($) | H8: Cuenta / Concepto | I8: Id Doc | K8: RESUMEN POR AUTORIZANTE · ¿En qué se gasta?
A9: ='reporte tsdocs del 1-6 al 7-6'!P2 -> Cristian Amaya | B9: ='reporte tsdocs del 1-6 al 7-6'!D2 -> IKES JUAN CARLOS | C9: 25 de Mayo | D9: Feedlot | E9: Flete de hacienda a Frigorífico La Anónima | F9: Verificado | G9: ='reporte tsdocs del 1-6 al 7-6'!L2 -> 2764850 | H9: Fletes | I9: 10771
A10: ='reporte tsdocs del 1-6 al 7-6'!P31 -> Cristian Amaya | B10: ='reporte tsdocs del 1-6 al 7-6'!D31 -> EMPRESA EL CEIBO SRL | C10: Winifreda | D10: Cría | E10: Pasajes de personal (salida de franco, mayo) | F10: Analista | G10: ='reporte tsdocs del 1-6 al 7-6'!L31 -> 140000 | H10: Personal | I10: 10799 | K10: Autorizante | L10: Campo / Locación | M10: Unidad / Centro de Costo | N10: Importe ($) | O10: % del total
A11: ='reporte tsdocs del 1-6 al 7-6'!P46 -> Cristian Amaya | B11: ='reporte tsdocs del 1-6 al 7-6'!D46 -> AGUADAS ALOMAR SRL | C11: Winifreda | D11: Cría | E11: Manta para tanque de Alto Pincén | F11: Analista | G11: ='reporte tsdocs del 1-6 al 7-6'!L46 -> 229200 | H11: Maquinaria | I11: 10808 | K11: Cristian Amaya | L11: 25 de Mayo | M11: Feedlot | N11: =SUMIFS($G$9:$G$26,$A$9:$A$26,$K11,$C$9:$C$26,L11,$D$9:$D$26,M11) -> 2764850 | O11: =N11/$G$27 -> 0.12086469
A12: ='reporte tsdocs del 1-6 al 7-6'!P49 -> Cristian Amaya | B12: ='reporte tsdocs del 1-6 al 7-6'!D49 -> GABINO RAUL PASCUAL | C12: Winifreda | D12: Cría | E12: Vacunas, varillas, raspaje 42 toros, sangrado Brucelosis | F12: Verificado | G12: ='reporte tsdocs del 1-6 al 7-6'!L49 -> 10229358 | H12: Sanidad / Veterinaria | I12: 10811 | L12: Winifreda | M12: Cría | N12: =SUMIFS($G$9:$G$26,$A$9:$A$26,$K11,$C$9:$C$26,L12,$D$9:$D$26,M12) -> 10598558 | O12: =N12/$G$27 -> 0.46331317
A13: ='reporte tsdocs del 1-6 al 7-6'!P6 -> Daniel Barruti | B13: ='reporte tsdocs del 1-6 al 7-6'!D6 -> GARCIA NICOLAS DANIEL | C13: 25 de Mayo | D13: Agricultura | E13: Agricultura | F13: Verificado | G13: ='reporte tsdocs del 1-6 al 7-6'!L6 -> 2887000 | H13: Honorarios Asesores Externos | I13: 10788
A14: ='reporte tsdocs del 1-6 al 7-6'!P10 -> Daniel Barruti | B14: ='reporte tsdocs del 1-6 al 7-6'!D10 -> GARCIA NICOLAS DANIEL | C14: 25 de Mayo | D14: Agricultura | E14: Agricultura | F14: Analista | G14: ='reporte tsdocs del 1-6 al 7-6'!L10 -> 2887000 | H14: Honorarios Asesores Externos | I14: 10789 | K14: Subtotal Cristian Amaya | N14: =SUMIFS($G$9:$G$26,$A$9:$A$26,$K11) -> 13363408 | O14: =N14/$G$27 -> 0.58417786
A15: ='reporte tsdocs del 1-6 al 7-6'!P13 -> Daniel Barruti | B15: ='reporte tsdocs del 1-6 al 7-6'!D13 -> HIDRAULICA CVC S.A.S. | C15: Ab Energía | D15: Planta | E15: AB Energía | F15: Analista | G15: ='reporte tsdocs del 1-6 al 7-6'!L13 -> 360607.24 | H15: Energía / Servicios | I15: 10790 | K15: Daniel Barruti | L15: 25 de Mayo | M15: Agricultura | N15: =SUMIFS($G$9:$G$26,$A$9:$A$26,$K15,$C$9:$C$26,L15,$D$9:$D$26,"Agricultura*") -> 6484927.5 | O15: =N15/$G$27 -> 0.28348689
A16: ='reporte tsdocs del 1-6 al 7-6'!P16 -> Daniel Barruti | B16: ='reporte tsdocs del 1-6 al 7-6'!D16 -> HIDRAULICA CVC S.A.S. | C16: 25 de Mayo | D16: Agricultura | E16: Empresa de maquinaria | F16: Analista | G16: ='reporte tsdocs del 1-6 al 7-6'!L16 -> 200700.25 | H16: Maquinaria | I16: 10791 | L16: 25 de Mayo | M16: A distribuir a Centro de Costo | N16: =SUMIFS($G$9:$G$26,$A$9:$A$26,$K15,$C$9:$C$26,L16,$D$9:$D$26,M16) -> 194634.31 | O16: =N16/$G$27 -> 0.0085083875
A17: ='reporte tsdocs del 1-6 al 7-6'!P22 -> Daniel Barruti | B17: ='reporte tsdocs del 1-6 al 7-6'!D22 -> TRANSPORTE EL PAMPERO SRL | C17: 25 de Mayo | D17: Agricultura | E17: Empresa de maquinaria | F17: Analista | G17: ='reporte tsdocs del 1-6 al 7-6'!L22 -> 37873 | H17: Maquinaria | I17: 10793 | L17: Ab Energía | M17: Planta | N17: =SUMIFS($G$9:$G$26,$A$9:$A$26,$K15,$C$9:$C$26,L17,$D$9:$D$26,M17) -> 1182611.4 | O17: =N17/$G$27 -> 0.051697546
A18: ='reporte tsdocs del 1-6 al 7-6'!P28 -> Daniel Barruti | B18: ='reporte tsdocs del 1-6 al 7-6'!D28 -> COOP REGIONAL DE PROV DE SERVICIOS PUB Y SOCIALES DEL OESTE PAMPEANO LTDA | C18: 25 de Mayo | D18: A distribuir a Centro de Costo | E18: Administración (sin asignar a CC operativo) | F18: Analista | G18: ='reporte tsdocs del 1-6 al 7-6'!L28 -> 60929.31 | H18: Administración | I18: 10795 | K18: Subtotal Daniel Barruti | N18: =SUMIFS($G$9:$G$26,$A$9:$A$26,$K15) -> 7862173.2 | O18: =N18/$G$27 -> 0.34369283
A19: ='reporte tsdocs del 1-6 al 7-6'!P19 -> Daniel Barruti | B19: ='reporte tsdocs del 1-6 al 7-6'!D19 -> TRANSPORTE EL PAMPERO SRL | C19: Ab Energía | D19: Planta | E19: AB Energía | F19: Analista | G19: ='reporte tsdocs del 1-6 al 7-6'!L19 -> 38962 | H19: Energía / Servicios | I19: 10792 | K19: Sandra Bartucci | L19: Ab Energía | M19: Planta | N19: =SUMIFS($G$9:$G$26,$A$9:$A$26,$K19,$C$9:$C$26,L19,$D$9:$D$26,M19) -> 1650000 | O19: =N19/$G$27 -> 0.072129314
A20: ='reporte tsdocs del 1-6 al 7-6'!P25 -> Daniel Barruti | B20: ='reporte tsdocs del 1-6 al 7-6'!D25 -> TRANSPORTE EL PAMPERO SRL | C20: 25 de Mayo | D20: Agricultura | E20: Empresa de maquinaria | F20: Analista | G20: ='reporte tsdocs del 1-6 al 7-6'!L25 -> 57838.67 | H20: Maquinaria | I20: 10794 | K20: Subtotal Sandra Bartucci | N20: =SUMIFS($G$9:$G$26,$A$9:$A$26,$K19) -> 1650000 | O20: =N20/$G$27 -> 0.072129314
A21: ='reporte tsdocs del 1-6 al 7-6'!P34 -> Daniel Barruti | B21: ='reporte tsdocs del 1-6 al 7-6'!D34 -> BERGONDI MIGUEL ANGEL | C21: 25 de Mayo | D21: A distribuir a Centro de Costo | E21: Personal (sin asignar a CC operativo) | F21: Analista | G21: ='reporte tsdocs del 1-6 al 7-6'!L34 -> 133705 | H21: Personal | I21: 10800 | K21: TOTAL GENERAL | N21: =SUM(N11:N12)+SUM(N15:N17)+N19 -> 22875581 | O21: =N21/$G$27 -> 1
A22: ='reporte tsdocs del 1-6 al 7-6'!P43 -> Daniel Barruti | B22: ='reporte tsdocs del 1-6 al 7-6'!D43 -> AC ELECTRICIDAD SAS | C22: 25 de Mayo | D22: Agricultura | E22: Empresa de maquinaria (generador portátil) | F22: Analista | G22: ='reporte tsdocs del 1-6 al 7-6'!L43 -> 414515.57 | H22: Maquinaria | I22: 10806
A23: ='reporte tsdocs del 1-6 al 7-6'!P37 -> Daniel Barruti | B23: ='reporte tsdocs del 1-6 al 7-6'!D37 -> TRANSPORTE EL PAMPERO SRL | C23: Ab Energía | D23: Planta | E23: AB Energía | F23: Analista | G23: ='reporte tsdocs del 1-6 al 7-6'!L37 -> 104080.19 | H23: Energía / Servicios | I23: 10801
A24: ='reporte tsdocs del 1-6 al 7-6'!P53 -> Daniel Barruti | B24: ='reporte tsdocs del 1-6 al 7-6'!D53 -> TRANSPORTE EL PAMPERO SRL | C24: Ab Energía | D24: Planta | E24: AB Energía | F24: Analista | G24: ='reporte tsdocs del 1-6 al 7-6'!L53 -> 38962 | H24: Energía / Servicios | I24: 10817
A25: ='reporte tsdocs del 1-6 al 7-6'!P56 -> Daniel Barruti | B25: ='reporte tsdocs del 1-6 al 7-6'!D56 -> GARRO MONICA ALEJANDRA | C25: Ab Energía | D25: Planta | E25: AB Energía (Daniel) | F25: Analista | G25: ='reporte tsdocs del 1-6 al 7-6'!L56 -> 640000 | H25: Energía / Servicios | I25: 10838
A26: ='reporte tsdocs del 1-6 al 7-6'!P40 -> Sandra Bartucci | B26: ='reporte tsdocs del 1-6 al 7-6'!D40 -> GONZALEZ IGNACIO GENARO | C26: Ab Energía | D26: Planta | E26: Servicio chillers J-501/J-502 (cableado por roedores) | F26: Analista | G26: ='reporte tsdocs del 1-6 al 7-6'!L40 -> 1650000 | H26: Mantenimiento Equipos | I26: 10804
E27: TOTAL GENERAL | G27: =SUM(G9:G26) -> 22875581
K28: Campo / Locación | N28: Importe ($) | O28: % del total
K29: 25 de Mayo | N29: =SUMIFS($G$9:$G$26,$C$9:$C$26,K29) -> 9444411.8 | O29: =N29/$G$27 -> 0.41285997
K30: Winifreda | N30: =SUMIFS($G$9:$G$26,$C$9:$C$26,K30) -> 10598558 | O30: =N30/$G$27 -> 0.46331317
A31: PROMPT REUTILIZABLE — Reporte semanal de gastos TSDOCS para Dirección | K31: Ab Energía | N31: =SUMIFS($G$9:$G$26,$C$9:$C$26,K31) -> 2832611.4 | O31: =N31/$G$27 -> 0.12382686
A32: Copiar y pegar este texto la próxima semana, junto con la nueva descarga de TSDOCS: | K32: TOTAL | N32: =SUM(N29:N31) -> 22875581 | O32: =N32/$G$27 -> 1
A34: Armá el reporte semanal de gastos de campo (TSDOCS) para Dirección, sobre la descarga cruda de la plataforma. Contexto: son gastos NO pagados ni contabilizados en Finnegans; están en TSDOCS. TSDOCS muestra UNA FILA POR CADA ESTADO que atravesó la factura, así que cada documento (col. A = Id Documento) aparece repetido. El importe (col. L) es ÚNICO por documento. Tomar UNA sola vez por documento el importe, y como estado válido EL MÁS AVANZADO según este orden: 1° Pivot → 2° Gerente → 3° Analista → 4° Verificado. ESTADOS (significado): Pivot = pendiente de autorizar (sin asignar) · Gerente = asignado a alguien pero pendiente de autorizar · Analista = autorizado, pendiente de pago (autorizante en col. P) · Verificado = contabilizado/pasado a pagar en Finnegans. INCLUIR TODOS los comprobantes; si el más avanzado es Pivot, en Autorizante poner 'Sin asignar'. CLASIFICACIÓN — separar Unidad de Cuenta: • UNIDAD / CENTRO DE COSTO = SOLO el nombre de la unidad de negocio: Planta, Agricultura, Feedlot, Cría (o 'A distribuir a Centro de Costo'). SIN '(Maquinaria)' ni '(Energía)'. • CUENTA CONTABLE (columna aparte) = tipo de gasto: Fletes, Maquinaria, Personal, Administración, Energía / Servicios, Sanidad / Veterinaria, Honorarios Asesores Externos, Mantenimiento Equipos (ej. servicio de chillers / reparación de equipos). Mapeo por Campo → Unidad (leer detalle col. R): • 25-FEED LOT → Campo 25 de Mayo · Unidad Feedlot • 25-EMPRESA MAQUINARIA → Campo 25 de Mayo · Unidad Agricultura · Cuenta Maquinaria • WINIFREDA / W → Campo Winifreda · Unidad SIEMPRE Cría (nunca 'A distribuir') • AB ENERGÍA → Campo Ab Energía · Unidad Planta (solo 'Planta') · Cuenta Energía / Servicios • 25-ADMINISTRACIÓN, 25-PERSONAL y demás CC de 25 no distribuibles → Campo 25 de Mayo · Unidad 'A distribuir a Centro de Costo'. REGLAS POR PROVEEDOR (prioridad): • GARCIA NICOLAS DANIEL → Campo 25 de Mayo · Unidad Agricultura · Cuenta 'Honorarios Asesores Externos' (NO maquinaria). • Servicios de reparación/mantenimiento de equipos (ej. chillers J-501/J-502) → Cuenta 'Mantenimiento Equipos'. Pulí el detalle de col. R (saca '=CC:...' y corrige codificación: Razón, ADMINISTRACIÓN, ENERGÍA). SALIDA en hoja 'Reporte Dirección' (data cruda intacta): 1) Título + período + nota de estados. 2) BANDA DE KPIs: Total $, Cantidad de comprobantes, 'Autorizado pend. pago' (suma Analista), 'Pasado a pagar' (suma Verificado). 3) Tabla DETALLE ORDENADA POR AUTORIZANTE, 1 fila por factura. Columnas: Autorizante · Proveedor · Campo · Unidad/CC · Detalle · Estado · Importe ($) · Cuenta Contable · Id Doc. Importe/Proveedor/Autorizante vinculados por fórmula a la fila del estado más avanzado en la cruda. Total con SUM. Columnas compactas (100% sin scroll). 4) Formato condicional: semáforo Estado (Verificado=verde, Analista=amarillo, Gerente=naranja, Pivot=gris); barras de datos en Importe. 5) RESUMEN POR AUTORIZANTE → Campo → Unidad (SUMIFS, subtotales, %). Línea Agricultura usar criterio 'Agricultura*'. 6) RESUMEN POR CAMPO (SUMIFS, %). 7) RESUMEN POR CUENTA CONTABLE (SUMIFS, %). 8) DASHBOARD aparte: KPIs + dona por Campo + barras por Cuenta + dona por Autorizante. Formato: importes $#,##0 (negativos entre paréntesis, ceros '-'); encabezados azul #1F4E78 texto blanco; subtotales gris. Español (es-AR). NOTA DE CONTROL: verificar que el total cuadre sumando importe único por documento. | K34: RESUMEN POR CUENTA / CONCEPTO
K36: Cuenta / Concepto | N36: Importe ($) | O36: % del total
K37: Maquinaria | N37: =SUMIFS($G$9:$G$26,$H$9:$H$26,K37) -> 940127.49 | O37: =N37/$G$27 -> 0.041097425
K38: Administración | N38: =SUMIFS($G$9:$G$26,$H$9:$H$26,K38) -> 60929.31 | O38: =N38/$G$27 -> 0.0026635087
K39: Personal | N39: =SUMIFS($G$9:$G$26,$H$9:$H$26,K39) -> 273705 | O39: =N39/$G$27 -> 0.011964942
K40: Fletes | N40: =SUMIFS($G$9:$G$26,$H$9:$H$26,K40) -> 2764850 | O40: =N40/$G$27 -> 0.12086469
K41: Energía / Servicios | N41: =SUMIFS($G$9:$G$26,$H$9:$H$26,K41) -> 1182611.4 | O41: =N41/$G$27 -> 0.051697546
K42: Sanidad / Veterinaria | N42: =SUMIFS($G$9:$G$26,$H$9:$H$26,K42) -> 10229358 | O42: =N42/$G$27 -> 0.44717369
K43: Honorarios Asesores Externos | N43: =SUMIFS($G$9:$G$26,$H$9:$H$26,K43) -> 5774000 | O43: =N43/$G$27 -> 0.25240889
K44: Mantenimiento Equipos | N44: =SUMIFS($G$9:$G$26,$H$9:$H$26,K44) -> 1650000 | O44: =N44/$G$27 -> 0.072129314
...

Sheet Dashboard
A1: DASHBOARD — Gastos de Campo TSDOCS
A2: Período 01/06 al 07/06 · Gastos no pagados ni contabilizados en Finnegans (plataforma TSDOCS)
A3: ="Esta semana: "&TEXT('Reporte Dirección'!G27,"$#.##0")&" en "&COUNTA('Reporte Dirección'!A9:A26)&" comprobantes. "&INDEX('Reporte Dirección'!K29:K31,MATCH(MAX('Reporte Dirección'!N29:N31),'Reporte Dirección'!N29:N31,0))&" concentra "&TEXT(MAX('Reporte Dirección'!N29:N31)/'Reporte Dirección'!G27,"0%")&" del gasto. Falta pasar a pago "&TEXT(SUMIF('Reporte Dirección'!F9:F26,"Analista",'Reporte Dirección'!G9:G26),"$#.##0")&"." -> Esta semana: $22.875.581 en 18 comprobantes. Winifreda concentra 46% del gasto. Falta pasar a pago $6.994.373.
A4: TOTAL DE GASTOS | C4: COMPROBANTES | E4: AUTORIZADO, PEND. PAGO | G4: PASADO A PAGAR
A5: ='Reporte Dirección'!G27 -> 22875581 | C5: =COUNTA('Reporte Dirección'!A9:A26) -> 18 | E5: =SUMIF('Reporte Dirección'!F9:F26,"Analista",'Reporte Dirección'!G9:G26) -> 6994373.2 | G5: =SUMIF('Reporte Dirección'!F9:F26,"Verificado",'Reporte Dirección'!G9:G26) -> 15881208
A26: TOP 3 GASTOS DE LA SEMANA | J26: HISTÓRICO SEMANAL
A27: Proveedor | D27: Concepto | F27: Importe | G27: % s/total | J27: Semana | L27: Total $ | M27: Comprob.
A28: =INDEX('Reporte Dirección'!$B$9:$B$26,MATCH(LARGE('Reporte Dirección'!$G$9:$G$26,1),'Reporte Dirección'!$G$9:$G$26,0)) -> GABINO RAUL PASCUAL | D28: =INDEX('Reporte Dirección'!$H$9:$H$26,MATCH(LARGE('Reporte Dirección'!$G$9:$G$26,1),'Reporte Dirección'!$G$9:$G$26,0)) -> Sanidad / Veterinaria | F28: =LARGE('Reporte Dirección'!$G$9:$G$26,1) -> 10229358 | G28: =F28/'Reporte Dirección'!$G$27 -> 0.44717369 | J28: 01/06 al 07/06 | L28: 22875581 | M28: 18
A29: =INDEX('Reporte Dirección'!$B$9:$B$26,MATCH(LARGE('Reporte Dirección'!$G$9:$G$26,2),'Reporte Dirección'!$G$9:$G$26,0)) -> GARCIA NICOLAS DANIEL | D29: =INDEX('Reporte Dirección'!$H$9:$H$26,MATCH(LARGE('Reporte Dirección'!$G$9:$G$26,2),'Reporte Dirección'!$G$9:$G$26,0)) -> Honorarios Asesores Externos | F29: =LARGE('Reporte Dirección'!$G$9:$G$26,2) -> 2887000 | G29: =F29/'Reporte Dirección'!$G$27 -> 0.12620444
A30: =INDEX('Reporte Dirección'!$B$9:$B$26,MATCH(LARGE('Reporte Dirección'!$G$9:$G$26,3),'Reporte Dirección'!$G$9:$G$26,0)) -> GARCIA NICOLAS DANIEL | D30: =INDEX('Reporte Dirección'!$H$9:$H$26,MATCH(LARGE('Reporte Dirección'!$G$9:$G$26,3),'Reporte Dirección'!$G$9:$G$26,0)) -> Honorarios Asesores Externos | F30: =LARGE('Reporte Dirección'!$G$9:$G$26,3) -> 2887000 | G30: =F30/'Reporte Dirección'!$G$27 -> 0.12620444 | J30: Agregá una fila por semana para ver el comparativo.
A44: Datos fuente de los gráficos (vinculados a Reporte Dirección)
A45: Por Campo | B45: Importe | D45: Por Cuenta | E45: Importe | G45: Por Autorizante | H45: Importe
A46: 25 de Mayo | B46: ='Reporte Dirección'!N29 -> 9444411.8 | D46: Maquinaria | E46: ='Reporte Dirección'!N37 -> 940127.49 | G46: Cristian Amaya | H46: ='Reporte Dirección'!N14 -> 13363408
A47: Winifreda | B47: ='Reporte Dirección'!N30 -> 10598558 | D47: Administración | E47: ='Reporte Dirección'!N38 -> 60929.31 | G47: Daniel Barruti | H47: ='Reporte Dirección'!N18 -> 7862173.2
A48: Ab Energía | B48: ='Reporte Dirección'!N31 -> 2832611.4 | D48: Personal | E48: ='Reporte Dirección'!N39 -> 273705 | G48: Sandra Bartucci | H48: ='Reporte Dirección'!N20 -> 1650000
D49: Fletes | E49: ='Reporte Dirección'!N40 -> 2764850
D50: Energía / Servicios | E50: ='Reporte Dirección'!N41 -> 1182611.4
D51: Sanidad / Veterinaria | E51: ='Reporte Dirección'!N42 -> 10229358
D52: Honorarios Asesores Externos | E52: ='Reporte Dirección'!N43 -> 5774000
D53: Mantenimiento Equipos | E53: ='Reporte Dirección'!N44 -> 1650000

Sheet reporte tsdocs del 1-6 al 7-6
A1: Id Documento | B1: Numero de factura | C1: CUIT | D1: RazÃ³n Social | E1: NÃºmero de acreedor | F1: Moneda | G1: Cotizacion | H1: Fecha de emisiÃ³n | I1: Orden de compra | J1: CAE | K1: Vencimiento CAE | L1: Importe | M1: Estado CAE | N1: Tipo de Documento | O1: Sociedad | P1: Autorizante | Q1: Fecha de autorizacion | R1: Detalle | S1: Fecha de Verificacion | T1: Usuario Verifica | U1: Fecha de Carga | V1: Usuario de Carga | W1: Estado del Workflow | X1: Grupo Asignado | Y1: Fecha Movimiento WF | Z1: Usuario Movimiento WF | AA1: ObservaciÃ³n
A2: 10771 | B2: 00005A00005786 | C2: 20170725310 | D2: IKES JUAN CARLOS | E2: 20170725310 | F2: PESO | G2: 1 | H2: 46169 | J2: 86217122528871 | K2: 46179 | L2: 2764850 | N2: Factura | O2: ABAG | P2: Cristian Amaya | Q2: 46174 | R2: Flete de Hacienda a Frigorifico de La Anonima =CC: 25-FEED LOT | S2: 46177 | T2: Daiana Ortega | U2: 46170.5 | V2: daiana.ortega@abagrosa.com | W2: Verificado | X2: Facturacion | Y2: 46177.417 | Z2: daiana.ortega@abagrosa.com
A3: 10771 | B3: 00005A00005786 | C3: 20170725310 | D3: IKES JUAN CARLOS | E3: 20170725310 | F3: PESO | G3: 1 | H3: 46169 | J3: 86217122528871 | K3: 46179 | L3: 2764850 | N3: Factura | O3: ABAG | P3: Cristian Amaya | Q3: 46174 | R3: Flete de Hacienda a Frigorifico de La Anonima =CC: 25-FEED LOT | S3: 46177 | T3: Daiana Ortega | U3: 46170.5 | V3: daiana.ortega@abagrosa.com | W3: Pivot | X3: Analista | Y3: 46170.5 | Z3: daiana.ortega@abagrosa.com
A4: 10771 | B4: 00005A00005786 | C4: 20170725310 | D4: IKES JUAN CARLOS | E4: 20170725310 | F4: PESO | G4: 1 | H4: 46169 | J4: 86217122528871 | K4: 46179 | L4: 2764850 | N4: Factura | O4: ABAG | P4: Cristian Amaya | Q4: 46174 | R4: Flete de Hacienda a Frigorifico de La Anonima =CC: 25-FEED LOT | S4: 46177 | T4: Daiana Ortega | U4: 46170.5 | V4: daiana.ortega@abagrosa.com | W4: Gerente | X4: AGRO | Y4: 46170.5 | Z4: daiana.ortega@abagrosa.com | AA4: AsignaciÃ³n AutomÃ¡tica
A5: 10771 | B5: 00005A00005786 | C5: 20170725310 | D5: IKES JUAN CARLOS | E5: 20170725310 | F5: PESO | G5: 1 | H5: 46169 | J5: 86217122528871 | K5: 46179 | L5: 2764850 | N5: Factura | O5: ABAG | P5: Cristian Amaya | Q5: 46174 | R5: Flete de Hacienda a Frigorifico de La Anonima =CC: 25-FEED LOT | S5: 46177 | T5: Daiana Ortega | U5: 46170.5 | V5: daiana.ortega@abagrosa.com | W5: Analista | X5: Analista | Y5: 46174.438 | Z5: cristian.amaya@abagrosa.com
A6: 10788 | B6: 00002C00000169 | C6: 23308238849 | D6: GARCIA NICOLAS DANIEL | E6: 23308238849 | F6: PESO | G6: 1 | H6: 46161 | J6: 86227500581316 | K6: 46171 | L6: 2887000 | N6: Factura | O6: ABAG | P6: Daniel Barruti | Q6: 46174 | R6: 25-ADMINISTRACIÃ“N | S6: 46177 | T6: Daiana Ortega | U6: 46174.341 | V6: daiana.ortega@abagrosa.com | W6: Verificado | X6: Facturacion | Y6: 46177.408 | Z6: daiana.ortega@abagrosa.com
A7: 10788 | B7: 00002C00000169 | C7: 23308238849 | D7: GARCIA NICOLAS DANIEL | E7: 23308238849 | F7: PESO | G7: 1 | H7: 46161 | J7: 86227500581316 | K7: 46171 | L7: 2887000 | N7: Factura | O7: ABAG | P7: Daniel Barruti | Q7: 46174 | R7: 25-ADMINISTRACIÃ“N | S7: 46177 | T7: Daiana Ortega | U7: 46174.341 | V7: daiana.ortega@abagrosa.com | W7: Pivot | X7: Analista | Y7: 46174.341 | Z7: daiana.ortega@abagrosa.com
A8: 10788 | B8: 00002C00000169 | C8: 23308238849 | D8: GARCIA NICOLAS DANIEL | E8: 23308238849 | F8: PESO | G8: 1 | H8: 46161 | J8: 86227500581316 | K8: 46171 | L8: 2887000 | N8: Factura | O8: ABAG | P8: Daniel Barruti | Q8: 46174 | R8: 25-ADMINISTRACIÃ“N | S8: 46177 | T8: Daiana Ortega | U8: 46174.341 | V8: daiana.ortega@abagrosa.com | W8: Gerente | X8: AGRO | Y8: 46174.341 | Z8: daiana.ortega@abagrosa.com | AA8: AsignaciÃ³n AutomÃ¡tica
A9: 10788 | B9: 00002C00000169 | C9: 23308238849 | D9: GARCIA NICOLAS DANIEL | E9: 23308238849 | F9: PESO | G9: 1 | H9: 46161 | J9: 86227500581316 | K9: 46171 | L9: 2887000 | N9: Factura | O9: ABAG | P9: Daniel Barruti | Q9: 46174 | R9: 25-ADMINISTRACIÃ“N | S9: 46177 | T9: Daiana Ortega | U9: 46174.341 | V9: daiana.ortega@abagrosa.com | W9: Analista | X9: Analista | Y9: 46174.412 | Z9: dbarruti@abagrosa.com
A10: 10789 | B10: 00002C00000170 | C10: 23308238849 | D10: GARCIA NICOLAS DANIEL | E10: 23308238849 | F10: PESO | G10: 1 | H10: 46171 | J10: 86227500851915 | K10: 46181 | L10: 2887000 | N10: Factura | O10: ABAG | P10: Daniel Barruti | Q10: 46174 | R10: 25-ADMINISTRACIÃ“N | U10: 46174.341 | V10: daiana.ortega@abagrosa.com | W10: Analista | X10: Facturacion | Y10: 46174.411 | Z10: dbarruti@abagrosa.com
A11: 10789 | B11: 00002C00000170 | C11: 23308238849 | D11: GARCIA NICOLAS DANIEL | E11: 23308238849 | F11: PESO | G11: 1 | H11: 46171 | J11: 86227500851915 | K11: 46181 | L11: 2887000 | N11: Factura | O11: ABAG | P11: Daniel Barruti | Q11: 46174 | R11: 25-ADMINISTRACIÃ“N | U11: 46174.341 | V11: daiana.ortega@abagrosa.com | W11: Pivot | X11: Analista | Y11: 46174.341 | Z11: daiana.ortega@abagrosa.com
A12: 10789 | B12: 00002C00000170 | C12: 23308238849 | D12: GARCIA NICOLAS DANIEL | E12: 23308238849 | F12: PESO | G12: 1 | H12: 46171 | J12: 86227500851915 | K12: 46181 | L12: 2887000 | N12: Factura | O12: ABAG | P12: Daniel Barruti | Q12: 46174 | R12: 25-ADMINISTRACIÃ“N | U12: 46174.341 | V12: daiana.ortega@abagrosa.com | W12: Gerente | X12: AGRO | Y12: 46174.341 | Z12: daiana.ortega@abagrosa.com | AA12: AsignaciÃ³n AutomÃ¡tica
A13: 10790 | B13: 00001A00016365 | C13: 30716700964 | D13: HIDRAULICA CVC S.A.S. | E13: 30716700964 | F13: PESO | G13: 1 | H13: 46171 | J13: 86227517941628 | K13: 46181 | L13: 360607.24 | N13: Factura | O13: ABEN | P13: Daniel Barruti | Q13: 46174 | R13: AB ENERGÃA | U13: 46174.342 | V13: daiana.ortega@abagrosa.com | W13: Analista | X13: Facturacion | Y13: 46174.411 | Z13: dbarruti@abagrosa.com
A14: 10790 | B14: 00001A00016365 | C14: 30716700964 | D14: HIDRAULICA CVC S.A.S. | E14: 30716700964 | F14: PESO | G14: 1 | H14: 46171 | J14: 86227517941628 | K14: 46181 | L14: 360607.24 | N14: Factura | O14: ABEN | P14: Daniel Barruti | Q14: 46174 | R14: AB ENERGÃA | U14: 46174.342 | V14: daiana.ortega@abagrosa.com | W14: Pivot | X14: Analista | Y14: 46174.342 | Z14: daiana.ortega@abagrosa.com
A15: 10790 | B15: 00001A00016365 | C15: 30716700964 | D15: HIDRAULICA CVC S.A.S. | E15: 30716700964 | F15: PESO | G15: 1 | H15: 46171 | J15: 86227517941628 | K15: 46181 | L15: 360607.24 | N15: Factura | O15: ABEN | P15: Daniel Barruti | Q15: 46174 | R15: AB ENERGÃA | U15: 46174.342 | V15: daiana.ortega@abagrosa.com | W15: Gerente | X15: ENERGIA | Y15: 46174.342 | Z15: daiana.ortega@abagrosa.com | AA15: AsignaciÃ³n AutomÃ¡tica
A16: 10791 | B16: 00001A00016256 | C16: 30716700964 | D16: HIDRAULICA CVC S.A.S. | E16: 30716700964 | F16: PESO | G16: 1 | H16: 46156 | L16: 200700.25 | N16: Factura | O16: ABAG | P16: Daniel Barruti | Q16: 46174 | R16: 25-EMPRESA MAQUINARIA | U16: 46174.343 | V16: daiana.ortega@abagrosa.com | W16: Analista | X16: Facturacion | Y16: 46174.41 | Z16: dbarruti@abagrosa.com
A17: 10791 | B17: 00001A00016256 | C17: 30716700964 | D17: HIDRAULICA CVC S.A.S. | E17: 30716700964 | F17: PESO | G17: 1 | H17: 46156 | L17: 200700.25 | N17: Factura | O17: ABAG | P17: Daniel Barruti | Q17: 46174 | R17: 25-EMPRESA MAQUINARIA | U17: 46174.343 | V17: daiana.ortega@abagrosa.com | W17: Pivot | X17: Analista | Y17: 46174.343 | Z17: daiana.ortega@abagrosa.com
A18: 10791 | B18: 00001A00016256 | C18: 30716700964 | D18: HIDRAULICA CVC S.A.S. | E18: 30716700964 | F18: PESO | G18: 1 | H18: 46156 | L18: 200700.25 | N18: Factura | O18: ABAG | P18: Daniel Barruti | Q18: 46174 | R18: 25-EMPRESA MAQUINARIA | U18: 46174.343 | V18: daiana.ortega@abagrosa.com | W18: Gerente | X18: AGRO | Y18: 46174.343 | Z18: daiana.ortega@abagrosa.com | AA18: AsignaciÃ³n AutomÃ¡tica
A19: 10792 | B19: 00010A00419893 | C19: 33709685479 | D19: TRANSPORTE EL PAMPERO SRL | E19: 33709685479 | F19: PESO | G19: 1 | H19: 46171 | J19: 86227400980364 | L19: 38962 | N19: Factura | O19: ABEN | P19: Daniel Barruti | Q19: 46175 | R19: AB ENERGÃA | U19: 46174.343 | V19: daiana.ortega@abagrosa.com | W19: Analista | X19: Facturacion | Y19: 46175.499 | Z19: dbarruti@abagrosa.com
A20: 10792 | B20: 00010A00419893 | C20: 33709685479 | D20: TRANSPORTE EL PAMPERO SRL | E20: 33709685479 | F20: PESO | G20: 1 | H20: 46171 | J20: 86227400980364 | L20: 38962 | N20: Factura | O20: ABEN | P20: Daniel Barruti | Q20: 46175 | R20: AB ENERGÃA | U20: 46174.343 | V20: daiana.ortega@abagrosa.com | W20: Pivot | X20: Analista | Y20: 46174.343 | Z20: daiana.ortega@abagrosa.com
A21: 10792 | B21: 00010A00419893 | C21: 33709685479 | D21: TRANSPORTE EL PAMPERO SRL | E21: 33709685479 | F21: PESO | G21: 1 | H21: 46171 | J21: 86227400980364 | L21: 38962 | N21: Factura | O21: ABEN | P21: Daniel Barruti | Q21: 46175 | R21: AB ENERGÃA | U21: 46174.343 | V21: daiana.ortega@abagrosa.com | W21: Gerente | X21: ENERGIA | Y21: 46174.343 | Z21: daiana.ortega@abagrosa.com | AA21: AsignaciÃ³n AutomÃ¡tica
A22: 10793 | B22: 00010A00419783 | C22: 33709685479 | D22: TRANSPORTE EL PAMPERO SRL | E22: 33709685479 | F22: PESO | G22: 1 | H22: 46170 | J22: 86227309635415 | L22: 37873 | N22: Factura | O22: ABAG | P22: Daniel Barruti | Q22: 46174 | R22: 25-EMPRESA MAQUINARIA | U22: 46174.344 | V22: daiana.ortega@abagrosa.com | W22: Analista | X22: Facturacion | Y22: 46174.408 | Z22: dbarruti@abagrosa.com | AA22: REPUESTO FONTANINI
A23: 10793 | B23: 00010A00419783 | C23: 33709685479 | D23: TRANSPORTE EL PAMPERO SRL | E23: 33709685479 | F23: PESO | G23: 1 | H23: 46170 | J23: 86227309635415 | L23: 37873 | N23: Factura | O23: ABAG | P23: Daniel Barruti | Q23: 46174 | R23: 25-EMPRESA MAQUINARIA | U23: 46174.344 | V23: daiana.ortega@abagrosa.com | W23: Pivot | X23: Analista | Y23: 46174.344 | Z23: daiana.ortega@abagrosa.com
A24: 10793 | B24: 00010A00419783 | C24: 33709685479 | D24: TRANSPORTE EL PAMPERO SRL | E24: 33709685479 | F24: PESO | G24: 1 | H24: 46170 | J24: 86227309635415 | L24: 37873 | N24: Factura | O24: ABAG | P24: Daniel Barruti | Q24: 46174 | R24: 25-EMPRESA MAQUINARIA | U24: 46174.344 | V24: daiana.ortega@abagrosa.com | W24: Gerente | X24: AGRO | Y24: 46174.344 | Z24: daiana.ortega@abagrosa.com | AA24: AsignaciÃ³n AutomÃ¡tica
A25: 10794 | B25: 00010A00419913 | C25: 33709685479 | D25: TRANSPORTE EL PAMPERO SRL | E25: 33709685479 | F25: PESO | G25: 1 | H25: 46171 | J25: 86227431871138 | L25: 57838.67 | N25: Factura | O25: ABAG | P25: Daniel Barruti | Q25: 46175 | R25: 25-EMPRESA MAQUINARIA | U25: 46174.347 | V25: daiana.ortega@abagrosa.com | W25: Analista | X25: Facturacion | Y25: 46175.493 | Z25: dbarruti@abagrosa.com | AA25: CUBIERTAS TBH
A26: 10794 | B26: 00010A00419913 | C26: 33709685479 | D26: TRANSPORTE EL PAMPERO SRL | E26: 33709685479 | F26: PESO | G26: 1 | H26: 46171 | J26: 86227431871138 | L26: 57838.67 | N26: Factura | O26: ABAG | P26: Daniel Barruti | Q26: 46175 | R26: 25-EMPRESA MAQUINARIA | U26: 46174.347 | V26: daiana.ortega@abagrosa.com | W26: Pivot | X26: Analista | Y26: 46174.347 | Z26: daiana.ortega@abagrosa.com
A27: 10794 | B27: 00010A00419913 | C27: 33709685479 | D27: TRANSPORTE EL PAMPERO SRL | E27: 33709685479 | F27: PESO | G27: 1 | H27: 46171 | J27: 86227431871138 | L27: 57838.67 | N27: Factura | O27: ABAG | P27: Daniel Barruti | Q27: 46175 | R27: 25-EMPRESA MAQUINARIA | U27: 46174.347 | V27: daiana.ortega@abagrosa.com | W27: Gerente | X27: AGRO | Y27: 46174.347 | Z27: daiana.ortega@abagrosa.com | AA27: AsignaciÃ³n AutomÃ¡tica
A28: 10795 | B28: 00006A00052756 | C28: 30608233330 | D28: COOP REGIONAL DE PROV DE SERVICIOS PUB Y SOCIALES DEL OESTE PAMPEANO LTDA | E28: 30608233330 | F28: PESO | G28: 1 | H28: 46169 | L28: 60929.31 | N28: Factura | O28: ABAG | P28: Daniel Barruti | Q28: 46174 | R28: 25-ADMINISTRACIÃ“N | U28: 46174.348 | V28: daiana.ortega@abagrosa.com | W28: Analista | X28: Facturacion | Y28: 46174.403 | Z28: dbarruti@abagrosa.com | AA28: ENERGÃA CASAS
A29: 10795 | B29: 00006A00052756 | C29: 30608233330 | D29: COOP REGIONAL DE PROV DE SERVICIOS PUB Y SOCIALES DEL OESTE PAMPEANO LTDA | E29: 30608233330 | F29: PESO | G29: 1 | H29: 46169 | L29: 60929.31 | N29: Factura | O29: ABAG | P29: Daniel Barruti | Q29: 46174 | R29: 25-ADMINISTRACIÃ“N | U29: 46174.348 | V29: daiana.ortega@abagrosa.com | W29: Pivot | X29: Analista | Y29: 46174.348 | Z29: daiana.ortega@abagrosa.com
A30: 10795 | B30: 00006A00052756 | C30: 30608233330 | D30: COOP REGIONAL DE PROV DE SERVICIOS PUB Y SOCIALES DEL OESTE PAMPEANO LTDA | E30: 30608233330 | F30: PESO | G30: 1 | H30: 46169 | L30: 60929.31 | N30: Factura | O30: ABAG | P30: Daniel Barruti | Q30: 46174 | R30: 25-ADMINISTRACIÃ“N | U30: 46174.348 | V30: daiana.ortega@abagrosa.com | W30: Gerente | X30: AGRO | Y30: 46174.348 | Z30: daiana.ortega@abagrosa.com | AA30: AsignaciÃ³n AutomÃ¡tica
A31: 10799 | B31: 00003A00003339 | C31: 33714177139 | D31: EMPRESA EL CEIBO SRL | E31: 33714177139 | F31: PESO | G31: 1 | J31: 86227815821405 | L31: 140000 | N31: Factura | O31: ABAG | P31: Cristian Amaya | Q31: 46175 | R31: Pasajes de Perez y Orueta en su salida de franco en mes de Mayo=CC: W-PERSONAL | U31: 46174.566 | V31: daiana.ortega@abagrosa.com | W31: Analista | X31: Facturacion | Y31: 46175.71 | Z31: cristian.amaya@abagrosa.com
A32: 10799 | B32: 00003A00003339 | C32: 33714177139 | D32: EMPRESA EL CEIBO SRL | E32: 33714177139 | F32: PESO | G32: 1 | J32: 86227815821405 | L32: 140000 | N32: Factura | O32: ABAG | P32: Cristian Amaya | Q32: 46175 | R32: Pasajes de Perez y Orueta en su salida de franco en mes de Mayo=CC: W-PERSONAL | U32: 46174.566 | V32: daiana.ortega@abagrosa.com | W32: Pivot | X32: Analista | Y32: 46174.566 | Z32: daiana.ortega@abagrosa.com
A33: 10799 | B33: 00003A00003339 | C33: 33714177139 | D33: EMPRESA EL CEIBO SRL | E33: 33714177139 | F33: PESO | G33: 1 | J33: 86227815821405 | L33: 140000 | N33: Factura | O33: ABAG | P33: Cristian Amaya | Q33: 46175 | R33: Pasajes de Perez y Orueta en su salida de franco en mes de Mayo=CC: W-PERSONAL | U33: 46174.566 | V33: daiana.ortega@abagrosa.com | W33: Gerente | X33: AGRO | Y33: 46174.566 | Z33: daiana.ortega@abagrosa.com | AA33: AsignaciÃ³n AutomÃ¡tica
A34: 10800 | B34: 00002A00004213 | C34: 20148209848 | D34: BERGONDI MIGUEL ANGEL | E34: 20148209848 | F34: PESO | G34: 1 | H34: 46174 | J34: 86227921527010 | K34: 46184 | L34: 133705 | N34: Factura | O34: ABAG | P34: Daniel Barruti | Q34: 46175 | R34: 25-PERSONAL | U34: 46175.41 | V34: daiana.ortega@abagrosa.com | W34: Analista | X34: Facturacion | Y34: 46175.492 | Z34: dbarruti@abagrosa.com
A35: 10800 | B35: 00002A00004213 | C35: 20148209848 | D35: BERGONDI MIGUEL ANGEL | E35: 20148209848 | F35: PESO | G35: 1 | H35: 46174 | J35: 86227921527010 | K35: 46184 | L35: 133705 | N35: Factura | O35: ABAG | P35: Daniel Barruti | Q35: 46175 | R35: 25-PERSONAL | U35: 46175.41 | V35: daiana.ortega@abagrosa.com | W35: Pivot | X35: Analista | Y35: 46175.41 | Z35: daiana.ortega@abagrosa.com
A36: 10800 | B36: 00002A00004213 | C36: 20148209848 | D36: BERGONDI MIGUEL ANGEL | E36: 20148209848 | F36: PESO | G36: 1 | H36: 46174 | J36: 86227921527010 | K36: 46184 | L36: 133705 | N36: Factura | O36: ABAG | P36: Daniel Barruti | Q36: 46175 | R36: 25-PERSONAL | U36: 46175.41 | V36: daiana.ortega@abagrosa.com | W36: Gerente | X36: AGRO | Y36: 46175.41 | Z36: daiana.ortega@abagrosa.com | AA36: AsignaciÃ³n AutomÃ¡tica
A37: 10801 | B37: 00010A00420117 | C37: 33709685479 | D37: TRANSPORTE EL PAMPERO SRL | E37: 33709685479 | F37: PESO | G37: 1 | H37: 46172 | J37: 86227598753675 | L37: 104080.19 | N37: Factura | O37: ABEN | P37: Daniel Barruti | Q37: 46178 | R37: AB ENERGÃA | U37: 46176.352 | V37: daiana.ortega@abagrosa.com | W37: Analista | X37: Facturacion | Y37: 46178.7 | Z37: dbarruti@abagrosa.com
A38: 10801 | B38: 00010A00420117 | C38: 33709685479 | D38: TRANSPORTE EL PAMPERO SRL | E38: 33709685479 | F38: PESO | G38: 1 | H38: 46172 | J38: 86227598753675 | L38: 104080.19 | N38: Factura | O38: ABEN | P38: Daniel Barruti | Q38: 46178 | R38: AB ENERGÃA | U38: 46176.352 | V38: daiana.ortega@abagrosa.com | W38: Pivot | X38: Analista | Y38: 46176.352 | Z38: daiana.ortega@abagrosa.com
A39: 10801 | B39: 00010A00420117 | C39: 33709685479 | D39: TRANSPORTE EL PAMPERO SRL | E39: 33709685479 | F39: PESO | G39: 1 | H39: 46172 | J39: 86227598753675 | L39: 104080.19 | N39: Factura | O39: ABEN | P39: Daniel Barruti | Q39: 46178 | R39: AB ENERGÃA | U39: 46176.352 | V39: daiana.ortega@abagrosa.com | W39: Gerente | X39: ENERGIA | Y39: 46176.352 | Z39: daiana.ortega@abagrosa.com | AA39: AsignaciÃ³n AutomÃ¡tica
A40: 10804 | B40: 00002C00000375 | C40: 20303123718 | D40: GONZALEZ IGNACIO GENARO | E40: 20303123718 | F40: PESO | G40: 1 | H40: 46175 | J40: 86228018345569 | K40: 46185 | L40: 1650000 | N40: Factura | O40: ABEN | P40: Sandra Bartucci | Q40: 46180 | R40: Servicios a J-501 y J-502 (Chillers). RevisiÃ³n cableado por daÃ±o por roedores | U40: 46176.355 | V40: daiana.ortega@abagrosa.com | W40: Analista | X40: Facturacion | Y40: 46180.754 | Z40: sandrabartucci
...
